-------------------------------------------------------------------------------
Test set: se.kth.iv1350.pos.integration.InventoryFailureExceptionTest
-------------------------------------------------------------------------------
Tests run: 2, Failures: 1, Errors: 0, Skipped: 0, Time elapsed: 0.002 s <<< FAILURE! - in se.kth.iv1350.pos.integration.InventoryFailureExceptionTest
testThrowable  Time elapsed: 0.001 s  <<< FAILURE!
org.opentest4j.AssertionFailedError: Unexpected exception type thrown ==> expected: <se.kth.iv1350.pos.integration.InvalidItemIDException> but was: <se.kth.iv1350.pos.integration.InventoryFailureException>
	at se.kth.iv1350.pos.integration.InventoryFailureExceptionTest.testThrowable(InventoryFailureExceptionTest.java:41)
Caused by: se.kth.iv1350.pos.integration.InventoryFailureException: Could not connect to database
	at se.kth.iv1350.pos.integration.InventoryFailureExceptionTest.lambda$testThrowable$1(InventoryFailureExceptionTest.java:42)
	at se.kth.iv1350.pos.integration.InventoryFailureExceptionTest.testThrowable(InventoryFailureExceptionTest.java:41)

